Workbook

Sheet 1-Data Input
B1: Monthly consumption | C1: Monthly production | D1: Avg_Daily_Con | E1: Avg_Daily_Prod
A2: January | D2: =B2/31 -> 0 | E2: =C2/31 -> 0
A3: February | D3: =B3/28 -> 0 | E3: =C3/28 -> 0
A4: March | D4: =B4/31 -> 0 | E4: =C4/31 -> 0
A5: April | D5: =B5/30 -> 0 | E5: =C5/30 -> 0
A6: May | D6: =B6/31 -> 0 | E6: =C6/31 -> 0
A7: June | D7: =B7/30 -> 0 | E7: =C7/30 -> 0
A8: July | D8: =B8/31 -> 0 | E8: =C8/31 -> 0
A9: August | D9: =B9/31 -> 0 | E9: =C9/31 -> 0
A10: September | D10: =B10/30 -> 0 | E10: =C10/30 -> 0
A11: October | D11: =B11/31 -> 0 | E11: =C11/31 -> 0
A12: November | D12: =B12/30 -> 0 | E12: =C12/30 -> 0
A13: December | D13: =B13/31 -> 0 | E13: =C13/31 -> 0
A14: Name of customer
A15: Consumption profile : | C15: Office building with gas heating, with A/C
A16: Production profile : | C16: Belgium

Sheet 2-Consumption profiles
A1: Consumption profile : | G1: Supermarket with electric heating, with A/C
A2: Relative Consumption | N2: Extrapolated Consumption | AB2: Consumption profiles
A3: H | B3: Jan | C3: Feb | D3: Mar | E3: Apr | F3: May | G3: Jun | H3: Jul | I3: Aug | J3: Sep | K3: Oct | L3: Nov | M3: Dec | N3: H | O3: Jan | P3: Feb | Q3: Mar | R3: Apr | S3: May | T3: Jun | U3: Jul | V3: Aug | W3: Sep | X3: Oct | Y3: Nov | Z3: Dec | AB3: =G1 -> Supermarket with electric heating, with A/C
A4: 0 | B4: 0.031716993 | C4: 0.03289899 | D4: 0.032635343 | E4: 0.034075372 | F4: 0.031788876 | G4: 0.032336472 | H4: 0.032914413 | I4: 0.032523731 | J4: 0.033621449 | K4: 0.033560424 | L4: 0.033132433 | M4: 0.032021031 | N4: 0 | O4: =B4*'1-Data Input'!$D$2 -> 0 | P4: =C4*'1-Data Input'!$D$3 -> 0 | Q4: =D4*'1-Data Input'!$D$4 -> 0 | R4: =E4*'1-Data Input'!$D$5 -> 0 | S4: =F4*'1-Data Input'!$D$6 -> 0 | T4: =G4*'1-Data Input'!$D$7 -> 0 | U4: =H4*'1-Data Input'!$D$8 -> 0 | V4: =I4*'1-Data Input'!$D$9 -> 0 | W4: =J4*'1-Data Input'!$D$10 -> 0 | X4: =K4*'1-Data Input'!$D$11 -> 0 | Y4: =L4*'1-Data Input'!$D$12 -> 0 | Z4: =M4*'1-Data Input'!$D$13 -> 0 | AB4: =G28 -> Supermarket with electric heating, no A/C
A5: 0.041666667 | B5: 0.032567815 | C5: 0.033645722 | D5: 0.033495587 | E5: 0.032637972 | F5: 0.03217471 | G5: 0.031574446 | H5: 0.032210666 | I5: 0.032110877 | J5: 0.0335637 | K5: 0.03306805 | L5: 0.032605557 | M5: 0.03239694 | N5: 0.041666667 | O5: =B5*'1-Data Input'!$D$2 -> 0 | P5: =C5*'1-Data Input'!$D$3 -> 0 | Q5: =D5*'1-Data Input'!$D$4 -> 0 | R5: =E5*'1-Data Input'!$D$5 -> 0 | S5: =F5*'1-Data Input'!$D$6 -> 0 | T5: =G5*'1-Data Input'!$D$7 -> 0 | U5: =H5*'1-Data Input'!$D$8 -> 0 | V5: =I5*'1-Data Input'!$D$9 -> 0 | W5: =J5*'1-Data Input'!$D$10 -> 0 | X5: =K5*'1-Data Input'!$D$11 -> 0 | Y5: =L5*'1-Data Input'!$D$12 -> 0 | Z5: =M5*'1-Data Input'!$D$13 -> 0 | AB5: =G55 -> Supermarket with gas heating, with A/C
A6: 0.083333333 | B6: 0.032911754 | C6: 0.032243356 | D6: 0.032100648 | E6: 0.032914375 | F6: 0.031324898 | G6: 0.03122423 | H6: 0.032099339 | I6: 0.032058451 | J6: 0.03246262 | K6: 0.033560424 | L6: 0.031781468 | M6: 0.032049352 | N6: 0.083333333 | O6: =B6*'1-Data Input'!$D$2 -> 0 | P6: =C6*'1-Data Input'!$D$3 -> 0 | Q6: =D6*'1-Data Input'!$D$4 -> 0 | R6: =E6*'1-Data Input'!$D$5 -> 0 | S6: =F6*'1-Data Input'!$D$6 -> 0 | T6: =G6*'1-Data Input'!$D$7 -> 0 | U6: =H6*'1-Data Input'!$D$8 -> 0 | V6: =I6*'1-Data Input'!$D$9 -> 0 | W6: =J6*'1-Data Input'!$D$10 -> 0 | X6: =K6*'1-Data Input'!$D$11 -> 0 | Y6: =L6*'1-Data Input'!$D$12 -> 0 | Z6: =M6*'1-Data Input'!$D$13 -> 0 | AB6: =G82 -> Supermarket with gas heating, no A/C
A7: 0.125 | B7: 0.032572091 | C7: 0.033692651 | D7: 0.033203161 | E7: 0.03325988 | F7: 0.029766998 | G7: 0.031878341 | H7: 0.031708369 | I7: 0.031357255 | J7: 0.031917855 | K7: 0.032596578 | L7: 0.033214758 | M7: 0.031809012 | N7: 0.125 | O7: =B7*'1-Data Input'!$D$2 -> 0 | P7: =C7*'1-Data Input'!$D$3 -> 0 | Q7: =D7*'1-Data Input'!$D$4 -> 0 | R7: =E7*'1-Data Input'!$D$5 -> 0 | S7: =F7*'1-Data Input'!$D$6 -> 0 | T7: =G7*'1-Data Input'!$D$7 -> 0 | U7: =H7*'1-Data Input'!$D$8 -> 0 | V7: =I7*'1-Data Input'!$D$9 -> 0 | W7: =J7*'1-Data Input'!$D$10 -> 0 | X7: =K7*'1-Data Input'!$D$11 -> 0 | Y7: =L7*'1-Data Input'!$D$12 -> 0 | Z7: =M7*'1-Data Input'!$D$13 -> 0 | AB7: =G109 -> Office building with electric heating, with A/C
A8: 0.16666667 | B8: 0.035024795 | C8: 0.035837607 | D8: 0.035426169 | E8: 0.035497529 | F8: 0.033512011 | G8: 0.034445406 | H8: 0.03423046 | I8: 0.032624651 | J8: 0.033457442 | K8: 0.03366726 | L8: 0.03331988 | M8: 0.033039967 | N8: 0.16666667 | O8: =B8*'1-Data Input'!$D$2 -> 0 | P8: =C8*'1-Data Input'!$D$3 -> 0 | Q8: =D8*'1-Data Input'!$D$4 -> 0 | R8: =E8*'1-Data Input'!$D$5 -> 0 | S8: =F8*'1-Data Input'!$D$6 -> 0 | T8: =G8*'1-Data Input'!$D$7 -> 0 | U8: =H8*'1-Data Input'!$D$8 -> 0 | V8: =I8*'1-Data Input'!$D$9 -> 0 | W8: =J8*'1-Data Input'!$D$10 -> 0 | X8: =K8*'1-Data Input'!$D$11 -> 0 | Y8: =L8*'1-Data Input'!$D$12 -> 0 | Z8: =M8*'1-Data Input'!$D$13 -> 0 | AB8: =G136 -> Office building with gas heating, with A/C
A9: 0.20833333 | B9: 0.041358218 | C9: 0.042595461 | D9: 0.0434854 | E9: 0.042903517 | F9: 0.04438779 | G9: 0.04704505 | H9: 0.042604738 | I9: 0.043487302 | J9: 0.042310744 | K9: 0.042293102 | L9: 0.04243721 | M9: 0.042852682 | N9: 0.20833333 | O9: =B9*'1-Data Input'!$D$2 -> 0 | P9: =C9*'1-Data Input'!$D$3 -> 0 | Q9: =D9*'1-Data Input'!$D$4 -> 0 | R9: =E9*'1-Data Input'!$D$5 -> 0 | S9: =F9*'1-Data Input'!$D$6 -> 0 | T9: =G9*'1-Data Input'!$D$7 -> 0 | U9: =H9*'1-Data Input'!$D$8 -> 0 | V9: =I9*'1-Data Input'!$D$9 -> 0 | W9: =J9*'1-Data Input'!$D$10 -> 0 | X9: =K9*'1-Data Input'!$D$11 -> 0 | Y9: =L9*'1-Data Input'!$D$12 -> 0 | Z9: =M9*'1-Data Input'!$D$13 -> 0 | AB9: =G163 -> Office building with electric heating, no A/C
A10: 0.25 | B10: 0.050856927 | C10: 0.049828132 | D10: 0.047512176 | E10: 0.047290915 | F10: 0.053154764 | G10: 0.052982947 | H10: 0.049494212 | I10: 0.051056295 | J10: 0.048820978 | K10: 0.050607726 | L10: 0.050933517 | M10: 0.052680364 | N10: 0.25 | O10: =B10*'1-Data Input'!$D$2 -> 0 | P10: =C10*'1-Data Input'!$D$3 -> 0 | Q10: =D10*'1-Data Input'!$D$4 -> 0 | R10: =E10*'1-Data Input'!$D$5 -> 0 | S10: =F10*'1-Data Input'!$D$6 -> 0 | T10: =G10*'1-Data Input'!$D$7 -> 0 | U10: =H10*'1-Data Input'!$D$8 -> 0 | V10: =I10*'1-Data Input'!$D$9 -> 0 | W10: =J10*'1-Data Input'!$D$10 -> 0 | X10: =K10*'1-Data Input'!$D$11 -> 0 | Y10: =L10*'1-Data Input'!$D$12 -> 0 | Z10: =M10*'1-Data Input'!$D$13 -> 0 | AB10: =G190 -> Papetterie
A11: 0.29166667 | B11: 0.050114417 | C11: 0.049513428 | D11: 0.049723827 | E11: 0.050197725 | F11: 0.050334037 | G11: 0.049533215 | H11: 0.048718898 | I11: 0.048782321 | J11: 0.046915262 | K11: 0.049102733 | L11: 0.050433238 | M11: 0.05074476 | N11: 0.29166667 | O11: =B11*'1-Data Input'!$D$2 -> 0 | P11: =C11*'1-Data Input'!$D$3 -> 0 | Q11: =D11*'1-Data Input'!$D$4 -> 0 | R11: =E11*'1-Data Input'!$D$5 -> 0 | S11: =F11*'1-Data Input'!$D$6 -> 0 | T11: =G11*'1-Data Input'!$D$7 -> 0 | U11: =H11*'1-Data Input'!$D$8 -> 0 | V11: =I11*'1-Data Input'!$D$9 -> 0 | W11: =J11*'1-Data Input'!$D$10 -> 0 | X11: =K11*'1-Data Input'!$D$11 -> 0 | Y11: =L11*'1-Data Input'!$D$12 -> 0 | Z11: =M11*'1-Data Input'!$D$13 -> 0 | AB11: =G190 -> Papetterie
A12: 0.33333333 | B12: 0.05241748 | C12: 0.051015173 | D12: 0.049097335 | E12: 0.050829795 | F12: 0.049922509 | G12: 0.04992619 | H12: 0.047181523 | I12: 0.047489148 | J12: 0.047816146 | K12: 0.049214214 | L12: 0.050011061 | M12: 0.050801298 | N12: 0.33333333 | O12: =B12*'1-Data Input'!$D$2 -> 0 | P12: =C12*'1-Data Input'!$D$3 -> 0 | Q12: =D12*'1-Data Input'!$D$4 -> 0 | R12: =E12*'1-Data Input'!$D$5 -> 0 | S12: =F12*'1-Data Input'!$D$6 -> 0 | T12: =G12*'1-Data Input'!$D$7 -> 0 | U12: =H12*'1-Data Input'!$D$8 -> 0 | V12: =I12*'1-Data Input'!$D$9 -> 0 | W12: =J12*'1-Data Input'!$D$10 -> 0 | X12: =K12*'1-Data Input'!$D$11 -> 0 | Y12: =L12*'1-Data Input'!$D$12 -> 0 | Z12: =M12*'1-Data Input'!$D$13 -> 0
A13: 0.375 | B13: 0.048947209 | C13: 0.052050384 | D13: 0.052572855 | E13: 0.051513182 | F13: 0.052940197 | G13: 0.049394248 | H13: 0.049626745 | I13: 0.04902479 | J13: 0.04841096 | K13: 0.048354881 | L13: 0.049806305 | M13: 0.052144082 | N13: 0.375 | O13: =B13*'1-Data Input'!$D$2 -> 0 | P13: =C13*'1-Data Input'!$D$3 -> 0 | Q13: =D13*'1-Data Input'!$D$4 -> 0 | R13: =E13*'1-Data Input'!$D$5 -> 0 | S13: =F13*'1-Data Input'!$D$6 -> 0 | T13: =G13*'1-Data Input'!$D$7 -> 0 | U13: =H13*'1-Data Input'!$D$8 -> 0 | V13: =I13*'1-Data Input'!$D$9 -> 0 | W13: =J13*'1-Data Input'!$D$10 -> 0 | X13: =K13*'1-Data Input'!$D$11 -> 0 | Y13: =L13*'1-Data Input'!$D$12 -> 0 | Z13: =M13*'1-Data Input'!$D$13 -> 0
A14: 0.41666667 | B14: 0.052634104 | C14: 0.051677708 | D14: 0.052046203 | E14: 0.052075643 | F14: 0.052090183 | G14: 0.050180708 | H14: 0.050669774 | I14: 0.05130925 | J14: 0.049197501 | K14: 0.050324379 | L14: 0.049794907 | M14: 0.052126621 | N14: 0.41666667 | O14: =B14*'1-Data Input'!$D$2 -> 0 | P14: =C14*'1-Data Input'!$D$3 -> 0 | Q14: =D14*'1-Data Input'!$D$4 -> 0 | R14: =E14*'1-Data Input'!$D$5 -> 0 | S14: =F14*'1-Data Input'!$D$6 -> 0 | T14: =G14*'1-Data Input'!$D$7 -> 0 | U14: =H14*'1-Data Input'!$D$8 -> 0 | V14: =I14*'1-Data Input'!$D$9 -> 0 | W14: =J14*'1-Data Input'!$D$10 -> 0 | X14: =K14*'1-Data Input'!$D$11 -> 0 | Y14: =L14*'1-Data Input'!$D$12 -> 0 | Z14: =M14*'1-Data Input'!$D$13 -> 0
A15: 0.45833333 | B15: 0.051077827 | C15: 0.04981893 | D15: 0.053024743 | E15: 0.051358213 | F15: 0.05211219 | G15: 0.050740646 | H15: 0.050795238 | I15: 0.051954089 | J15: 0.050033706 | K15: 0.05080127 | L15: 0.050137714 | M15: 0.052588905 | N15: 0.45833333 | O15: =B15*'1-Data Input'!$D$2 -> 0 | P15: =C15*'1-Data Input'!$D$3 -> 0 | Q15: =D15*'1-Data Input'!$D$4 -> 0 | R15: =E15*'1-Data Input'!$D$5 -> 0 | S15: =F15*'1-Data Input'!$D$6 -> 0 | T15: =G15*'1-Data Input'!$D$7 -> 0 | U15: =H15*'1-Data Input'!$D$8 -> 0 | V15: =I15*'1-Data Input'!$D$9 -> 0 | W15: =J15*'1-Data Input'!$D$10 -> 0 | X15: =K15*'1-Data Input'!$D$11 -> 0 | Y15: =L15*'1-Data Input'!$D$12 -> 0 | Z15: =M15*'1-Data Input'!$D$13 -> 0
A16: 0.5 | B16: 0.051605137 | C16: 0.050352639 | D16: 0.052083112 | E16: 0.050651962 | F16: 0.051628039 | G16: 0.050577755 | H16: 0.051866542 | I16: 0.051233232 | J16: 0.050564997 | K16: 0.049760006 | L16: 0.05103484 | M16: 0.051121404 | N16: 0.5 | O16: =B16*'1-Data Input'!$D$2 -> 0 | P16: =C16*'1-Data Input'!$D$3 -> 0 | Q16: =D16*'1-Data Input'!$D$4 -> 0 | R16: =E16*'1-Data Input'!$D$5 -> 0 | S16: =F16*'1-Data Input'!$D$6 -> 0 | T16: =G16*'1-Data Input'!$D$7 -> 0 | U16: =H16*'1-Data Input'!$D$8 -> 0 | V16: =I16*'1-Data Input'!$D$9 -> 0 | W16: =J16*'1-Data Input'!$D$10 -> 0 | X16: =K16*'1-Data Input'!$D$11 -> 0 | Y16: =L16*'1-Data Input'!$D$12 -> 0 | Z16: =M16*'1-Data Input'!$D$13 -> 0
A17: 0.54166667 | B17: 0.04917381 | C17: 0.048657654 | D17: 0.049712471 | E17: 0.049722148 | F17: 0.05256553 | G17: 0.050156274 | H17: 0.051464969 | I17: 0.051251582 | J17: 0.049955168 | K17: 0.048457072 | L17: 0.049399749 | M17: 0.050460405 | N17: 0.54166667 | O17: =B17*'1-Data Input'!$D$2 -> 0 | P17: =C17*'1-Data Input'!$D$3 -> 0 | Q17: =D17*'1-Data Input'!$D$4 -> 0 | R17: =E17*'1-Data Input'!$D$5 -> 0 | S17: =F17*'1-Data Input'!$D$6 -> 0 | T17: =G17*'1-Data Input'!$D$7 -> 0 | U17: =H17*'1-Data Input'!$D$8 -> 0 | V17: =I17*'1-Data Input'!$D$9 -> 0 | W17: =J17*'1-Data Input'!$D$10 -> 0 | X17: =K17*'1-Data Input'!$D$11 -> 0 | Y17: =L17*'1-Data Input'!$D$12 -> 0 | Z17: =M17*'1-Data Input'!$D$13 -> 0
A18: 0.58333333 | B18: 0.047989974 | C18: 0.047601279 | D18: 0.04926768 | E18: 0.048878711 | F18: 0.05043967 | G18: 0.048236192 | H18: 0.049593612 | I18: 0.048922123 | J18: 0.04755435 | K18: 0.046953627 | L18: 0.048921845 | M18: 0.047117996 | N18: 0.58333333 | O18: =B18*'1-Data Input'!$D$2 -> 0 | P18: =C18*'1-Data Input'!$D$3 -> 0 | Q18: =D18*'1-Data Input'!$D$4 -> 0 | R18: =E18*'1-Data Input'!$D$5 -> 0 | S18: =F18*'1-Data Input'!$D$6 -> 0 | T18: =G18*'1-Data Input'!$D$7 -> 0 | U18: =H18*'1-Data Input'!$D$8 -> 0 | V18: =I18*'1-Data Input'!$D$9 -> 0 | W18: =J18*'1-Data Input'!$D$10 -> 0 | X18: =K18*'1-Data Input'!$D$11 -> 0 | Y18: =L18*'1-Data Input'!$D$12 -> 0 | Z18: =M18*'1-Data Input'!$D$13 -> 0
A19: 0.625 | B19: 0.046674074 | C19: 0.046018557 | D19: 0.046106826 | E19: 0.046140081 | F19: 0.04847556 | G19: 0.047164673 | H19: 0.046962844 | I19: 0.04627243 | J19: 0.046845963 | K19: 0.046131068 | L19: 0.046082706 | M19: 0.046363459 | N19: 0.625 | O19: =B19*'1-Data Input'!$D$2 -> 0 | P19: =C19*'1-Data Input'!$D$3 -> 0 | Q19: =D19*'1-Data Input'!$D$4 -> 0 | R19: =E19*'1-Data Input'!$D$5 -> 0 | S19: =F19*'1-Data Input'!$D$6 -> 0 | T19: =G19*'1-Data Input'!$D$7 -> 0 | U19: =H19*'1-Data Input'!$D$8 -> 0 | V19: =I19*'1-Data Input'!$D$9 -> 0 | W19: =J19*'1-Data Input'!$D$10 -> 0 | X19: =K19*'1-Data Input'!$D$11 -> 0 | Y19: =L19*'1-Data Input'!$D$12 -> 0 | Z19: =M19*'1-Data Input'!$D$13 -> 0
A20: 0.66666667 | B20: 0.042629463 | C20: 0.042954334 | D20: 0.043148494 | E20: 0.041960494 | F20: 0.044147915 | G20: 0.044359379 | H20: 0.044610395 | I20: 0.044430969 | J20: 0.045584726 | K20: 0.043319656 | L20: 0.043056965 | M20: 0.043361527 | N20: 0.66666667 | O20: =B20*'1-Data Input'!$D$2 -> 0 | P20: =C20*'1-Data Input'!$D$3 -> 0 | Q20: =D20*'1-Data Input'!$D$4 -> 0 | R20: =E20*'1-Data Input'!$D$5 -> 0 | S20: =F20*'1-Data Input'!$D$6 -> 0 | T20: =G20*'1-Data Input'!$D$7 -> 0 | U20: =H20*'1-Data Input'!$D$8 -> 0 | V20: =I20*'1-Data Input'!$D$9 -> 0 | W20: =J20*'1-Data Input'!$D$10 -> 0 | X20: =K20*'1-Data Input'!$D$11 -> 0 | Y20: =L20*'1-Data Input'!$D$12 -> 0 | Z20: =M20*'1-Data Input'!$D$13 -> 0
A21: 0.70833333 | B21: 0.039752535 | C21: 0.038583446 | D21: 0.036463383 | E21: 0.037924189 | F21: 0.039029125 | G21: 0.039725121 | H21: 0.040581411 | I21: 0.040499025 | J21: 0.041764054 | K21: 0.040667338 | L21: 0.038857151 | M21: 0.038296363 | N21: 0.70833333 | O21: =B21*'1-Data Input'!$D$2 -> 0 | P21: =C21*'1-Data Input'!$D$3 -> 0 | Q21: =D21*'1-Data Input'!$D$4 -> 0 | R21: =E21*'1-Data Input'!$D$5 -> 0 | S21: =F21*'1-Data Input'!$D$6 -> 0 | T21: =G21*'1-Data Input'!$D$7 -> 0 | U21: =H21*'1-Data Input'!$D$8 -> 0 | V21: =I21*'1-Data Input'!$D$9 -> 0 | W21: =J21*'1-Data Input'!$D$10 -> 0 | X21: =K21*'1-Data Input'!$D$11 -> 0 | Y21: =L21*'1-Data Input'!$D$12 -> 0 | Z21: =M21*'1-Data Input'!$D$13 -> 0
A22: 0.75 | B22: 0.037417643 | C22: 0.037488423 | D22: 0.03804381 | E22: 0.037687925 | F22: 0.035700591 | G22: 0.037398829 | H22: 0.038268721 | I22: 0.03826437 | J22: 0.038801532 | K22: 0.038315785 | L22: 0.038964806 | M22: 0.037321494 | N22: 0.75 | O22: =B22*'1-Data Input'!$D$2 -> 0 | P22: =C22*'1-Data Input'!$D$3 -> 0 | Q22: =D22*'1-Data Input'!$D$4 -> 0 | R22: =E22*'1-Data Input'!$D$5 -> 0 | S22: =F22*'1-Data Input'!$D$6 -> 0 | T22: =G22*'1-Data Input'!$D$7 -> 0 | U22: =H22*'1-Data Input'!$D$8 -> 0 | V22: =I22*'1-Data Input'!$D$9 -> 0 | W22: =J22*'1-Data Input'!$D$10 -> 0 | X22: =K22*'1-Data Input'!$D$11 -> 0 | Y22: =L22*'1-Data Input'!$D$12 -> 0 | Z22: =M22*'1-Data Input'!$D$13 -> 0
A23: 0.79166667 | B23: 0.037470374 | C23: 0.03698048 | D23: 0.036272218 | E23: 0.036204797 | F23: 0.034508921 | G23: 0.035648766 | H23: 0.03714087 | I23: 0.037631327 | J23: 0.037717006 | K23: 0.03808005 | L23: 0.036359553 | M23: 0.036023192 | N23: 0.79166667 | O23: =B23*'1-Data Input'!$D$2 -> 0 | P23: =C23*'1-Data Input'!$D$3 -> 0 | Q23: =D23*'1-Data Input'!$D$4 -> 0 | R23: =E23*'1-Data Input'!$D$5 -> 0 | S23: =F23*'1-Data Input'!$D$6 -> 0 | T23: =G23*'1-Data Input'!$D$7 -> 0 | U23: =H23*'1-Data Input'!$D$8 -> 0 | V23: =I23*'1-Data Input'!$D$9 -> 0 | W23: =J23*'1-Data Input'!$D$10 -> 0 | X23: =K23*'1-Data Input'!$D$11 -> 0 | Y23: =L23*'1-Data Input'!$D$12 -> 0 | Z23: =M23*'1-Data Input'!$D$13 -> 0
... A27: 0.95833333 | B27: 0.032854748 | C27: 0.033172745 | D27: 0.032876666 | E27: 0.032365633 | F27: 0.032229013 | G27: 0.033128022 | H27: 0.032912204 | I27: 0.033430263 | J27: 0.034988175 | K27: 0.033436556 | L27: 0.033394183 | M27: 0.031927493 | N27: 0.95833333 | O27: =B27*'1-Data Input'!$D$2 -> 0 | P27: =C27*'1-Data Input'!$D$3 -> 0 | Q27: =D27*'1-Data Input'!$D$4 -> 0 | R27: =E27*'1-Data Input'!$D$5 -> 0 | S27: =F27*'1-Data Input'!$D$6 -> 0 | T27: =G27*'1-Data Input'!$D$7 -> 0 | U27: =H27*'1-Data Input'!$D$8 -> 0 | V27: =I27*'1-Data Input'!$D$9 -> 0 | W27: =J27*'1-Data Input'!$D$10 -> 0 | X27: =K27*'1-Data Input'!$D$11 -> 0 | Y27: =L27*'1-Data Input'!$D$12 -> 0 | Z27: =M27*'1-Data Input'!$D$13 -> 0
A28: Consumption profile : | G28: Supermarket with electric heating, no A/C
A29: Relative Consumption | N29: Extrapolated Consumption
A30: H | B30: Jan | C30: Feb | D30: Mar | E30: Apr | F30: May | G30: Jun | H30: Jul | I30: Aug | J30: Sep | K30: Oct | L30: Nov | M30: Dec | N30: H | O30: Jan | P30: Feb | Q30: Mar | R30: Apr | S30: May | T30: Jun | U30: Jul | V30: Aug | W30: Sep | X30: Oct | Y30: Nov | Z30: Dec
A31: 0 | B31: 0.031716993 | C31: 0.03289899 | D31: 0.032635343 | E31: 0.034075372 | F31: 0.031788876 | G31: 0.032336472 | H31: 0.032914413 | I31: 0.032523731 | J31: 0.033621449 | K31: 0.033560424 | L31: 0.033132433 | M31: 0.032021031 | N31: 0 | O31: =B31*'1-Data Input'!$D$2 -> 0 | P31: =C31*'1-Data Input'!$D$3 -> 0 | Q31: =D31*'1-Data Input'!$D$4 -> 0 | R31: =E31*'1-Data Input'!$D$5 -> 0 | S31: =F31*'1-Data Input'!$D$6 -> 0 | T31: =G31*'1-Data Input'!$D$7 -> 0 | U31: =H31*'1-Data Input'!$D$8 -> 0 | V31: =I31*'1-Data Input'!$D$9 -> 0 | W31: =J31*'1-Data Input'!$D$10 -> 0 | X31: =K31*'1-Data Input'!$D$11 -> 0 | Y31: =L31*'1-Data Input'!$D$12 -> 0 | Z31: =M31*'1-Data Input'!$D$13 -> 0
A32: 0.041666667 | B32: 0.032567815 | C32: 0.033645722 | D32: 0.033495587 | E32: 0.032637972 | F32: 0.03217471 | G32: 0.031574446 | H32: 0.032210666 | I32: 0.032110877 | J32: 0.0335637 | K32: 0.03306805 | L32: 0.032605557 | M32: 0.03239694 | N32: 0.041666667 | O32: =B32*'1-Data Input'!$D$2 -> 0 | P32: =C32*'1-Data Input'!$D$3 -> 0 | Q32: =D32*'1-Data Input'!$D$4 -> 0 | R32: =E32*'1-Data Input'!$D$5 -> 0 | S32: =F32*'1-Data Input'!$D$6 -> 0 | T32: =G32*'1-Data Input'!$D$7 -> 0 | U32: =H32*'1-Data Input'!$D$8 -> 0 | V32: =I32*'1-Data Input'!$D$9 -> 0 | W32: =J32*'1-Data Input'!$D$10 -> 0 | X32: =K32*'1-Data Input'!$D$11 -> 0 | Y32: =L32*'1-Data Input'!$D$12 -> 0 | Z32: =M32*'1-Data Input'!$D$13 -> 0
A33: 0.083333333 | B33: 0.032911754 | C33: 0.032243356 | D33: 0.032100648 | E33: 0.032914375 | F33: 0.031324898 | G33: 0.03122423 | H33: 0.032099339 | I33: 0.032058451 | J33: 0.03246262 | K33: 0.033560424 | L33: 0.031781468 | M33: 0.032049352 | N33: 0.083333333 | O33: =B33*'1-Data Input'!$D$2 -> 0 | P33: =C33*'1-Data Input'!$D$3 -> 0 | Q33: =D33*'1-Data Input'!$D$4 -> 0 | R33: =E33*'1-Data Input'!$D$5 -> 0 | S33: =F33*'1-Data Input'!$D$6 -> 0 | T33: =G33*'1-Data Input'!$D$7 -> 0 | U33: =H33*'1-Data Input'!$D$8 -> 0 | V33: =I33*'1-Data Input'!$D$9 -> 0 | W33: =J33*'1-Data Input'!$D$10 -> 0 | X33: =K33*'1-Data Input'!$D$11 -> 0 | Y33: =L33*'1-Data Input'!$D$12 -> 0 | Z33: =M33*'1-Data Input'!$D$13 -> 0
A34: 0.125 | B34: 0.032572091 | C34: 0.033692651 | D34: 0.033203161 | E34: 0.03325988 | F34: 0.029766998 | G34: 0.031878341 | H34: 0.031708369 | I34: 0.031357255 | J34: 0.031917855 | K34: 0.032596578 | L34: 0.033214758 | M34: 0.031809012 | N34: 0.125 | O34: =B34*'1-Data Input'!$D$2 -> 0 | P34: =C34*'1-Data Input'!$D$3 -> 0 | Q34: =D34*'1-Data Input'!$D$4 -> 0 | R34: =E34*'1-Data Input'!$D$5 -> 0 | S34: =F34*'1-Data Input'!$D$6 -> 0 | T34: =G34*'1-Data Input'!$D$7 -> 0 | U34: =H34*'1-Data Input'!$D$8 -> 0 | V34: =I34*'1-Data Input'!$D$9 -> 0 | W34: =J34*'1-Data Input'!$D$10 -> 0 | X34: =K34*'1-Data Input'!$D$11 -> 0 | Y34: =L34*'1-Data Input'!$D$12 -> 0 | Z34: =M34*'1-Data Input'!$D$13 -> 0
A35: 0.16666667 | B35: 0.035024795 | C35: 0.035837607 | D35: 0.035426169 | E35: 0.035497529 | F35: 0.033512011 | G35: 0.034445406 | H35: 0.03423046 | I35: 0.032624651 | J35: 0.033457442 | K35: 0.03366726 | L35: 0.03331988 | M35: 0.033039967 | N35: 0.16666667 | O35: =B35*'1-Data Input'!$D$2 -> 0 | P35: =C35*'1-Data Input'!$D$3 -> 0 | Q35: =D35*'1-Data Input'!$D$4 -> 0 | R35: =E35*'1-Data Input'!$D$5 -> 0 | S35: =F35*'1-Data Input'!$D$6 -> 0 | T35: =G35*'1-Data Input'!$D$7 -> 0 | U35: =H35*'1-Data Input'!$D$8 -> 0 | V35: =I35*'1-Data Input'!$D$9 -> 0 | W35: =J35*'1-Data Input'!$D$10 -> 0 | X35: =K35*'1-Data Input'!$D$11 -> 0 | Y35: =L35*'1-Data Input'!$D$12 -> 0 | Z35: =M35*'1-Data Input'!$D$13 -> 0
A36: 0.20833333 | B36: 0.041358218 | C36: 0.042595461 | D36: 0.0434854 | E36: 0.042903517 | F36: 0.04438779 | G36: 0.04704505 | H36: 0.042604738 | I36: 0.043487302 | J36: 0.042310744 | K36: 0.042293102 | L36: 0.04243721 | M36: 0.042852682 | N36: 0.20833333 | O36: =B36*'1-Data Input'!$D$2 -> 0 | P36: =C36*'1-Data Input'!$D$3 -> 0 | Q36: =D36*'1-Data Input'!$D$4 -> 0 | R36: =E36*'1-Data Input'!$D$5 -> 0 | S36: =F36*'1-Data Input'!$D$6 -> 0 | T36: =G36*'1-Data Input'!$D$7 -> 0 | U36: =H36*'1-Data Input'!$D$8 -> 0 | V36: =I36*'1-Data Input'!$D$9 -> 0 | W36: =J36*'1-Data Input'!$D$10 -> 0 | X36: =K36*'1-Data Input'!$D$11 -> 0 | Y36: =L36*'1-Data Input'!$D$12 -> 0 | Z36: =M36*'1-Data Input'!$D$13 -> 0
A37: 0.25 | B37: 0.050856927 | C37: 0.049828132 | D37: 0.047512176 | E37: 0.047290915 | F37: 0.053154764 | G37: 0.052982947 | H37: 0.049494212 | I37: 0.051056295 | J37: 0.048820978 | K37: 0.050607726 | L37: 0.050933517 | M37: 0.052680364 | N37: 0.25 | O37: =B37*'1-Data Input'!$D$2 -> 0 | P37: =C37*'1-Data Input'!$D$3 -> 0 | Q37: =D37*'1-Data Input'!$D$4 -> 0 | R37: =E37*'1-Data Input'!$D$5 -> 0 | S37: =F37*'1-Data Input'!$D$6 -> 0 | T37: =G37*'1-Data Input'!$D$7 -> 0 | U37: =H37*'1-Data Input'!$D$8 -> 0 | V37: =I37*'1-Data Input'!$D$9 -> 0 | W37: =J37*'1-Data Input'!$D$10 -> 0 | X37: =K37*'1-Data Input'!$D$11 -> 0 | Y37: =L37*'1-Data Input'!$D$12 -> 0 | Z37: =M37*'1-Data Input'!$D$13 -> 0
A38: 0.29166667 | B38: 0.050114417 | C38: 0.049513428 | D38: 0.049723827 | E38: 0.050197725 | F38: 0.050334037 | G38: 0.049533215 | H38: 0.048718898 | I38: 0.048782321 | J38: 0.046915262 | K38: 0.049102733 | L38: 0.050433238 | M38: 0.05074476 | N38: 0.29166667 | O38: =B38*'1-Data Input'!$D$2 -> 0 | P38: =C38*'1-Data Input'!$D$3 -> 0 | Q38: =D38*'1-Data Input'!$D$4 -> 0 | R38: =E38*'1-Data Input'!$D$5 -> 0 | S38: =F38*'1-Data Input'!$D$6 -> 0 | T38: =G38*'1-Data Input'!$D$7 -> 0 | U38: =H38*'1-Data Input'!$D$8 -> 0 | V38: =I38*'1-Data Input'!$D$9 -> 0 | W38: =J38*'1-Data Input'!$D$10 -> 0 | X38: =K38*'1-Data Input'!$D$11 -> 0 | Y38: =L38*'1-Data Input'!$D$12 -> 0 | Z38: =M38*'1-Data Input'!$D$13 -> 0
A39: 0.33333333 | B39: 0.05241748 | C39: 0.051015173 | D39: 0.049097335 | E39: 0.050829795 | F39: 0.049922509 | G39: 0.04992619 | H39: 0.047181523 | I39: 0.047489148 | J39: 0.047816146 | K39: 0.049214214 | L39: 0.050011061 | M39: 0.050801298 | N39: 0.33333333 | O39: =B39*'1-Data Input'!$D$2 -> 0 | P39: =C39*'1-Data Input'!$D$3 -> 0 | Q39: =D39*'1-Data Input'!$D$4 -> 0 | R39: =E39*'1-Data Input'!$D$5 -> 0 | S39: =F39*'1-Data Input'!$D$6 -> 0 | T39: =G39*'1-Data Input'!$D$7 -> 0 | U39: =H39*'1-Data Input'!$D$8 -> 0 | V39: =I39*'1-Data Input'!$D$9 -> 0 | W39: =J39*'1-Data Input'!$D$10 -> 0 | X39: =K39*'1-Data Input'!$D$11 -> 0 | Y39: =L39*'1-Data Input'!$D$12 -> 0 | Z39: =M39*'1-Data Input'!$D$13 -> 0
A40: 0.375 | B40: 0.048947209 | C40: 0.052050384 | D40: 0.052572855 | E40: 0.051513182 | F40: 0.052940197 | G40: 0.049394248 | H40: 0.049626745 | I40: 0.04902479 | J40: 0.04841096 | K40: 0.048354881 | L40: 0.049806305 | M40: 0.052144082 | N40: 0.375 | O40: =B40*'1-Data Input'!$D$2 -> 0 | P40: =C40*'1-Data Input'!$D$3 -> 0 | Q40: =D40*'1-Data Input'!$D$4 -> 0 | R40: =E40*'1-Data Input'!$D$5 -> 0 | S40: =F40*'1-Data Input'!$D$6 -> 0 | T40: =G40*'1-Data Input'!$D$7 -> 0 | U40: =H40*'1-Data Input'!$D$8 -> 0 | V40: =I40*'1-Data Input'!$D$9 -> 0 | W40: =J40*'1-Data Input'!$D$10 -> 0 | X40: =K40*'1-Data Input'!$D$11 -> 0 | Y40: =L40*'1-Data Input'!$D$12 -> 0 | Z40: =M40*'1-Data Input'!$D$13 -> 0
A41: 0.41666667 | B41: 0.052634104 | C41: 0.051677708 | D41: 0.052046203 | E41: 0.052075643 | F41: 0.052090183 | G41: 0.050180708 | H41: 0.050669774 | I41: 0.05130925 | J41: 0.049197501 | K41: 0.050324379 | L41: 0.049794907 | M41: 0.052126621 | N41: 0.41666667 | O41: =B41*'1-Data Input'!$D$2 -> 0 | P41: =C41*'1-Data Input'!$D$3 -> 0 | Q41: =D41*'1-Data Input'!$D$4 -> 0 | R41: =E41*'1-Data Input'!$D$5 -> 0 | S41: =F41*'1-Data Input'!$D$6 -> 0 | T41: =G41*'1-Data Input'!$D$7 -> 0 | U41: =H41*'1-Data Input'!$D$8 -> 0 | V41: =I41*'1-Data Input'!$D$9 -> 0 | W41: =J41*'1-Data Input'!$D$10 -> 0 | X41: =K41*'1-Data Input'!$D$11 -> 0 | Y41: =L41*'1-Data Input'!$D$12 -> 0 | Z41: =M41*'1-Data Input'!$D$13 -> 0
A42: 0.45833333 | B42: 0.051077827 | C42: 0.04981893 | D42: 0.053024743 | E42: 0.051358213 | F42: 0.05211219 | G42: 0.050740646 | H42: 0.050795238 | I42: 0.051954089 | J42: 0.050033706 | K42: 0.05080127 | L42: 0.050137714 | M42: 0.052588905 | N42: 0.45833333 | O42: =B42*'1-Data Input'!$D$2 -> 0 | P42: =C42*'1-Data Input'!$D$3 -> 0 | Q42: =D42*'1-Data Input'!$D$4 -> 0 | R42: =E42*'1-Data Input'!$D$5 -> 0 | S42: =F42*'1-Data Input'!$D$6 -> 0 | T42: =G42*'1-Data Input'!$D$7 -> 0 | U42: =H42*'1-Data Input'!$D$8 -> 0 | V42: =I42*'1-Data Input'!$D$9 -> 0 | W42: =J42*'1-Data Input'!$D$10 -> 0 | X42: =K42*'1-Data Input'!$D$11 -> 0 | Y42: =L42*'1-Data Input'!$D$12 -> 0 | Z42: =M42*'1-Data Input'!$D$13 -> 0
... A54: 0.95833333 | B54: 0.032854748 | C54: 0.033172745 | D54: 0.032876666 | E54: 0.032365633 | F54: 0.032229013 | G54: 0.033128022 | H54: 0.032912204 | I54: 0.033430263 | J54: 0.034988175 | K54: 0.033436556 | L54: 0.033394183 | M54: 0.031927493 | N54: 0.95833333 | O54: =B54*'1-Data Input'!$D$2 -> 0 | P54: =C54*'1-Data Input'!$D$3 -> 0 | Q54: =D54*'1-Data Input'!$D$4 -> 0 | R54: =E54*'1-Data Input'!$D$5 -> 0 | S54: =F54*'1-Data Input'!$D$6 -> 0 | T54: =G54*'1-Data Input'!$D$7 -> 0 | U54: =H54*'1-Data Input'!$D$8 -> 0 | V54: =I54*'1-Data Input'!$D$9 -> 0 | W54: =J54*'1-Data Input'!$D$10 -> 0 | X54: =K54*'1-Data Input'!$D$11 -> 0 | Y54: =L54*'1-Data Input'!$D$12 -> 0 | Z54: =M54*'1-Data Input'!$D$13 -> 0
...

Sheet 3-Production profile
A1: Production profile : | G1: Belgium
A2: Relative Production | N2: Extrapolated Production | AB2: Production profiles
A3: H | B3: Jan | C3: Feb | D3: Mar | E3: Apr | F3: May | G3: Jun | H3: Jul | I3: Aug | J3: Sep | K3: Oct | L3: Nov | M3: Dec | N3: H | O3: Jan | P3: Feb | Q3: Mar | R3: Apr | S3: May | T3: Jun | U3: Jul | V3: Aug | W3: Sep | X3: Oct | Y3: Nov | Z3: Dec | AB3: =G1 -> Belgium
A4: 0 | B4: 0 | C4: 0 | D4: 0 | E4: 0 | F4: 0 | G4: 0 | H4: 0 | I4: 0 | J4: 0 | K4: 0 | L4: 0 | M4: 0 | N4: 0 | O4: =B4*'1-Data Input'!$E$2 -> 0 | P4: =C4*'1-Data Input'!$E$3 -> 0 | Q4: =D4*'1-Data Input'!$E$4 -> 0 | R4: =E4*'1-Data Input'!$E$5 -> 0 | S4: =F4*'1-Data Input'!$E$6 -> 0 | T4: =G4*'1-Data Input'!$E$7 -> 0 | U4: =H4*'1-Data Input'!$E$8 -> 0 | V4: =I4*'1-Data Input'!$E$9 -> 0 | W4: =J4*'1-Data Input'!$E$10 -> 0 | X4: =K4*'1-Data Input'!$E$11 -> 0 | Y4: =L4*'1-Data Input'!$E$12 -> 0 | Z4: =M4*'1-Data Input'!$E$13 -> 0 | AB4: =G28 -> Northern France
A5: 0.041666667 | B5: 0 | C5: 0 | D5: 0 | E5: 0 | F5: 0 | G5: 0 | H5: 0 | I5: 0 | J5: 0 | K5: 0 | L5: 0 | M5: 0 | N5: 0.041666667 | O5: =B5*'1-Data Input'!$E$2 -> 0 | P5: =C5*'1-Data Input'!$E$3 -> 0 | Q5: =D5*'1-Data Input'!$E$4 -> 0 | R5: =E5*'1-Data Input'!$E$5 -> 0 | S5: =F5*'1-Data Input'!$E$6 -> 0 | T5: =G5*'1-Data Input'!$E$7 -> 0 | U5: =H5*'1-Data Input'!$E$8 -> 0 | V5: =I5*'1-Data Input'!$E$9 -> 0 | W5: =J5*'1-Data Input'!$E$10 -> 0 | X5: =K5*'1-Data Input'!$E$11 -> 0 | Y5: =L5*'1-Data Input'!$E$12 -> 0 | Z5: =M5*'1-Data Input'!$E$13 -> 0 | AB5: =G55 -> Eastern France
A6: 0.083333333 | B6: 0 | C6: 0 | D6: 0 | E6: 0 | F6: 0 | G6: 0 | H6: 0 | I6: 0 | J6: 0 | K6: 0 | L6: 0 | M6: 0 | N6: 0.083333333 | O6: =B6*'1-Data Input'!$E$2 -> 0 | P6: =C6*'1-Data Input'!$E$3 -> 0 | Q6: =D6*'1-Data Input'!$E$4 -> 0 | R6: =E6*'1-Data Input'!$E$5 -> 0 | S6: =F6*'1-Data Input'!$E$6 -> 0 | T6: =G6*'1-Data Input'!$E$7 -> 0 | U6: =H6*'1-Data Input'!$E$8 -> 0 | V6: =I6*'1-Data Input'!$E$9 -> 0 | W6: =J6*'1-Data Input'!$E$10 -> 0 | X6: =K6*'1-Data Input'!$E$11 -> 0 | Y6: =L6*'1-Data Input'!$E$12 -> 0 | Z6: =M6*'1-Data Input'!$E$13 -> 0 | AB6: =G82 -> Western France
A7: 0.125 | B7: 0 | C7: 0 | D7: 0 | E7: 0 | F7: 0 | G7: 0 | H7: 0 | I7: 0 | J7: 0 | K7: 0 | L7: 0 | M7: 0 | N7: 0.125 | O7: =B7*'1-Data Input'!$E$2 -> 0 | P7: =C7*'1-Data Input'!$E$3 -> 0 | Q7: =D7*'1-Data Input'!$E$4 -> 0 | R7: =E7*'1-Data Input'!$E$5 -> 0 | S7: =F7*'1-Data Input'!$E$6 -> 0 | T7: =G7*'1-Data Input'!$E$7 -> 0 | U7: =H7*'1-Data Input'!$E$8 -> 0 | V7: =I7*'1-Data Input'!$E$9 -> 0 | W7: =J7*'1-Data Input'!$E$10 -> 0 | X7: =K7*'1-Data Input'!$E$11 -> 0 | Y7: =L7*'1-Data Input'!$E$12 -> 0 | Z7: =M7*'1-Data Input'!$E$13 -> 0 | AB7: =G109 -> Central France
A8: 0.16666667 | B8: 0 | C8: 0 | D8: 0 | E8: 0 | F8: 0 | G8: 0 | H8: 0 | I8: 0 | J8: 0 | K8: 0 | L8: 0 | M8: 0 | N8: 0.16666667 | O8: =B8*'1-Data Input'!$E$2 -> 0 | P8: =C8*'1-Data Input'!$E$3 -> 0 | Q8: =D8*'1-Data Input'!$E$4 -> 0 | R8: =E8*'1-Data Input'!$E$5 -> 0 | S8: =F8*'1-Data Input'!$E$6 -> 0 | T8: =G8*'1-Data Input'!$E$7 -> 0 | U8: =H8*'1-Data Input'!$E$8 -> 0 | V8: =I8*'1-Data Input'!$E$9 -> 0 | W8: =J8*'1-Data Input'!$E$10 -> 0 | X8: =K8*'1-Data Input'!$E$11 -> 0 | Y8: =L8*'1-Data Input'!$E$12 -> 0 | Z8: =M8*'1-Data Input'!$E$13 -> 0 | AB8: =G136 -> Custom made - Pacapime
A9: 0.20833333 | B9: 0 | C9: 0 | D9: 0 | E9: 0 | F9: 0.0016694641 | G9: 0.0066202879 | H9: 0.0019306895 | I9: 0 | J9: 0 | K9: 0 | L9: 0 | M9: 0 | N9: 0.20833333 | O9: =B9*'1-Data Input'!$E$2 -> 0 | P9: =C9*'1-Data Input'!$E$3 -> 0 | Q9: =D9*'1-Data Input'!$E$4 -> 0 | R9: =E9*'1-Data Input'!$E$5 -> 0 | S9: =F9*'1-Data Input'!$E$6 -> 0 | T9: =G9*'1-Data Input'!$E$7 -> 0 | U9: =H9*'1-Data Input'!$E$8 -> 0 | V9: =I9*'1-Data Input'!$E$9 -> 0 | W9: =J9*'1-Data Input'!$E$10 -> 0 | X9: =K9*'1-Data Input'!$E$11 -> 0 | Y9: =L9*'1-Data Input'!$E$12 -> 0 | Z9: =M9*'1-Data Input'!$E$13 -> 0
A10: 0.25 | B10: 0 | C10: 0 | D10: 0 | E10: 0.0040167692 | F10: 0.016239159 | G10: 0.020198459 | H10: 0.015534043 | I10: 0.008546055 | J10: 6.859195e-05 | K10: 0 | L10: 0 | M10: 0 | N10: 0.25 | O10: =B10*'1-Data Input'!$E$2 -> 0 | P10: =C10*'1-Data Input'!$E$3 -> 0 | Q10: =D10*'1-Data Input'!$E$4 -> 0 | R10: =E10*'1-Data Input'!$E$5 -> 0 | S10: =F10*'1-Data Input'!$E$6 -> 0 | T10: =G10*'1-Data Input'!$E$7 -> 0 | U10: =H10*'1-Data Input'!$E$8 -> 0 | V10: =I10*'1-Data Input'!$E$9 -> 0 | W10: =J10*'1-Data Input'!$E$10 -> 0 | X10: =K10*'1-Data Input'!$E$11 -> 0 | Y10: =L10*'1-Data Input'!$E$12 -> 0 | Z10: =M10*'1-Data Input'!$E$13 -> 0
A11: 0.29166667 | B11: 0 | C11: 0 | D11: 0.0059357523 | E11: 0.02756773 | F11: 0.042436399 | G11: 0.045794582 | H11: 0.040167483 | I11: 0.035338462 | J11: 0.01830796 | K11: 0.0028633054 | L11: 0.00089330427 | M11: 0 | N11: 0.29166667 | O11: =B11*'1-Data Input'!$E$2 -> 0 | P11: =C11*'1-Data Input'!$E$3 -> 0 | Q11: =D11*'1-Data Input'!$E$4 -> 0 | R11: =E11*'1-Data Input'!$E$5 -> 0 | S11: =F11*'1-Data Input'!$E$6 -> 0 | T11: =G11*'1-Data Input'!$E$7 -> 0 | U11: =H11*'1-Data Input'!$E$8 -> 0 | V11: =I11*'1-Data Input'!$E$9 -> 0 | W11: =J11*'1-Data Input'!$E$10 -> 0 | X11: =K11*'1-Data Input'!$E$11 -> 0 | Y11: =L11*'1-Data Input'!$E$12 -> 0 | Z11: =M11*'1-Data Input'!$E$13 -> 0
A12: 0.33333333 | B12: 0 | C12: 0.0054723383 | D12: 0.036925596 | E12: 0.059886227 | F12: 0.071021361 | G12: 0.06970555 | H12: 0.06491654 | I12: 0.064866111 | J12: 0.050210942 | K12: 0.036782153 | L12: 0.018917531 | M12: 0.0063451587 | N12: 0.33333333 | O12: =B12*'1-Data Input'!$E$2 -> 0 | P12: =C12*'1-Data Input'!$E$3 -> 0 | Q12: =D12*'1-Data Input'!$E$4 -> 0 | R12: =E12*'1-Data Input'!$E$5 -> 0 | S12: =F12*'1-Data Input'!$E$6 -> 0 | T12: =G12*'1-Data Input'!$E$7 -> 0 | U12: =H12*'1-Data Input'!$E$8 -> 0 | V12: =I12*'1-Data Input'!$E$9 -> 0 | W12: =J12*'1-Data Input'!$E$10 -> 0 | X12: =K12*'1-Data Input'!$E$11 -> 0 | Y12: =L12*'1-Data Input'!$E$12 -> 0 | Z12: =M12*'1-Data Input'!$E$13 -> 0
A13: 0.375 | B13: 0.022603022 | C13: 0.049162935 | D13: 0.076237312 | E13: 0.090771844 | F13: 0.092683636 | G13: 0.089369119 | H13: 0.089106656 | I13: 0.090597644 | J13: 0.086391761 | K13: 0.087049798 | L13: 0.072839329 | M13: 0.046005884 | N13: 0.375 | O13: =B13*'1-Data Input'!$E$2 -> 0 | P13: =C13*'1-Data Input'!$E$3 -> 0 | Q13: =D13*'1-Data Input'!$E$4 -> 0 | R13: =E13*'1-Data Input'!$E$5 -> 0 | S13: =F13*'1-Data Input'!$E$6 -> 0 | T13: =G13*'1-Data Input'!$E$7 -> 0 | U13: =H13*'1-Data Input'!$E$8 -> 0 | V13: =I13*'1-Data Input'!$E$9 -> 0 | W13: =J13*'1-Data Input'!$E$10 -> 0 | X13: =K13*'1-Data Input'!$E$11 -> 0 | Y13: =L13*'1-Data Input'!$E$12 -> 0 | Z13: =M13*'1-Data Input'!$E$13 -> 0
A14: 0.41666667 | B14: 0.11875715 | C14: 0.093211644 | D14: 0.10586585 | E14: 0.10833984 | F14: 0.11060387 | G14: 0.10355447 | H14: 0.10735759 | I14: 0.10501304 | J14: 0.10802933 | K14: 0.13277957 | L14: 0.13443926 | M14: 0.11370772 | N14: 0.41666667 | O14: =B14*'1-Data Input'!$E$2 -> 0 | P14: =C14*'1-Data Input'!$E$3 -> 0 | Q14: =D14*'1-Data Input'!$E$4 -> 0 | R14: =E14*'1-Data Input'!$E$5 -> 0 | S14: =F14*'1-Data Input'!$E$6 -> 0 | T14: =G14*'1-Data Input'!$E$7 -> 0 | U14: =H14*'1-Data Input'!$E$8 -> 0 | V14: =I14*'1-Data Input'!$E$9 -> 0 | W14: =J14*'1-Data Input'!$E$10 -> 0 | X14: =K14*'1-Data Input'!$E$11 -> 0 | Y14: =L14*'1-Data Input'!$E$12 -> 0 | Z14: =M14*'1-Data Input'!$E$13 -> 0
A15: 0.45833333 | B15: 0.18836314 | C15: 0.12008607 | D15: 0.12025077 | E15: 0.11877613 | F15: 0.11264811 | G15: 0.093992291 | H15: 0.10311793 | I15: 0.11568575 | J15: 0.12799489 | K15: 0.15325271 | L15: 0.16527374 | M15: 0.16481105 | N15: 0.45833333 | O15: =B15*'1-Data Input'!$E$2 -> 0 | P15: =C15*'1-Data Input'!$E$3 -> 0 | Q15: =D15*'1-Data Input'!$E$4 -> 0 | R15: =E15*'1-Data Input'!$E$5 -> 0 | S15: =F15*'1-Data Input'!$E$6 -> 0 | T15: =G15*'1-Data Input'!$E$7 -> 0 | U15: =H15*'1-Data Input'!$E$8 -> 0 | V15: =I15*'1-Data Input'!$E$9 -> 0 | W15: =J15*'1-Data Input'!$E$10 -> 0 | X15: =K15*'1-Data Input'!$E$11 -> 0 | Y15: =L15*'1-Data Input'!$E$12 -> 0 | Z15: =M15*'1-Data Input'!$E$13 -> 0
A16: 0.5 | B16: 0.19319641 | C16: 0.15032753 | D16: 0.13728411 | E16: 0.12224564 | F16: 0.10973739 | G16: 0.10145338 | H16: 0.1124978 | I16: 0.11864355 | J16: 0.13768054 | K16: 0.16832734 | L16: 0.1662397 | M16: 0.18665166 | N16: 0.5 | O16: =B16*'1-Data Input'!$E$2 -> 0 | P16: =C16*'1-Data Input'!$E$3 -> 0 | Q16: =D16*'1-Data Input'!$E$4 -> 0 | R16: =E16*'1-Data Input'!$E$5 -> 0 | S16: =F16*'1-Data Input'!$E$6 -> 0 | T16: =G16*'1-Data Input'!$E$7 -> 0 | U16: =H16*'1-Data Input'!$E$8 -> 0 | V16: =I16*'1-Data Input'!$E$9 -> 0 | W16: =J16*'1-Data Input'!$E$10 -> 0 | X16: =K16*'1-Data Input'!$E$11 -> 0 | Y16: =L16*'1-Data Input'!$E$12 -> 0 | Z16: =M16*'1-Data Input'!$E$13 -> 0
A17: 0.54166667 | B17: 0.19292014 | C17: 0.17599678 | D17: 0.15413759 | E17: 0.12979365 | F17: 0.10583021 | G17: 0.10022466 | H17: 0.11474482 | I17: 0.11546269 | J17: 0.14432087 | K17: 0.15634303 | L17: 0.18279465 | M17: 0.220248 | N17: 0.54166667 | O17: =B17*'1-Data Input'!$E$2 -> 0 | P17: =C17*'1-Data Input'!$E$3 -> 0 | Q17: =D17*'1-Data Input'!$E$4 -> 0 | R17: =E17*'1-Data Input'!$E$5 -> 0 | S17: =F17*'1-Data Input'!$E$6 -> 0 | T17: =G17*'1-Data Input'!$E$7 -> 0 | U17: =H17*'1-Data Input'!$E$8 -> 0 | V17: =I17*'1-Data Input'!$E$9 -> 0 | W17: =J17*'1-Data Input'!$E$10 -> 0 | X17: =K17*'1-Data Input'!$E$11 -> 0 | Y17: =L17*'1-Data Input'!$E$12 -> 0 | Z17: =M17*'1-Data Input'!$E$13 -> 0
A18: 0.58333333 | B18: 0.17063363 | C18: 0.18802565 | D18: 0.14083148 | E18: 0.12211345 | F18: 0.10096308 | G18: 0.10112498 | H18: 0.10281795 | I18: 0.10787116 | J18: 0.13254998 | K18: 0.12861595 | L18: 0.1489127 | M18: 0.18131454 | N18: 0.58333333 | O18: =B18*'1-Data Input'!$E$2 -> 0 | P18: =C18*'1-Data Input'!$E$3 -> 0 | Q18: =D18*'1-Data Input'!$E$4 -> 0 | R18: =E18*'1-Data Input'!$E$5 -> 0 | S18: =F18*'1-Data Input'!$E$6 -> 0 | T18: =G18*'1-Data Input'!$E$7 -> 0 | U18: =H18*'1-Data Input'!$E$8 -> 0 | V18: =I18*'1-Data Input'!$E$9 -> 0 | W18: =J18*'1-Data Input'!$E$10 -> 0 | X18: =K18*'1-Data Input'!$E$11 -> 0 | Y18: =L18*'1-Data Input'!$E$12 -> 0 | Z18: =M18*'1-Data Input'!$E$13 -> 0
A19: 0.625 | B19: 0.10016734 | C19: 0.14237261 | D19: 0.10886859 | E19: 0.099176918 | F19: 0.090436479 | G19: 0.094617067 | H19: 0.089637644 | I19: 0.091658443 | J19: 0.095941577 | K19: 0.093335141 | L19: 0.087334178 | M19: 0.072839435 | N19: 0.625 | O19: =B19*'1-Data Input'!$E$2 -> 0 | P19: =C19*'1-Data Input'!$E$3 -> 0 | Q19: =D19*'1-Data Input'!$E$4 -> 0 | R19: =E19*'1-Data Input'!$E$5 -> 0 | S19: =F19*'1-Data Input'!$E$6 -> 0 | T19: =G19*'1-Data Input'!$E$7 -> 0 | U19: =H19*'1-Data Input'!$E$8 -> 0 | V19: =I19*'1-Data Input'!$E$9 -> 0 | W19: =J19*'1-Data Input'!$E$10 -> 0 | X19: =K19*'1-Data Input'!$E$11 -> 0 | Y19: =L19*'1-Data Input'!$E$12 -> 0 | Z19: =M19*'1-Data Input'!$E$13 -> 0
A20: 0.66666667 | B20: 0.013359177 | C20: 0.066497349 | D20: 0.078859298 | E20: 0.068865201 | F20: 0.069853749 | G20: 0.077164857 | H20: 0.071668132 | I20: 0.073026919 | J20: 0.064787931 | K20: 0.037478475 | L20: 0.021171806 | M20: 0.0080765658 | N20: 0.66666667 | O20: =B20*'1-Data Input'!$E$2 -> 0 | P20: =C20*'1-Data Input'!$E$3 -> 0 | Q20: =D20*'1-Data Input'!$E$4 -> 0 | R20: =E20*'1-Data Input'!$E$5 -> 0 | S20: =F20*'1-Data Input'!$E$6 -> 0 | T20: =G20*'1-Data Input'!$E$7 -> 0 | U20: =H20*'1-Data Input'!$E$8 -> 0 | V20: =I20*'1-Data Input'!$E$9 -> 0 | W20: =J20*'1-Data Input'!$E$10 -> 0 | X20: =K20*'1-Data Input'!$E$11 -> 0 | Y20: =L20*'1-Data Input'!$E$12 -> 0 | Z20: =M20*'1-Data Input'!$E$13 -> 0
... A27: 0.95833333 | B27: 0 | C27: 0 | D27: 0 | E27: 0 | F27: 0 | G27: 0 | H27: 0 | I27: 0 | J27: 0 | K27: 0 | L27: 0 | M27: 0 | N27: 0.95833333 | O27: =B27*'1-Data Input'!$E$2 -> 0 | P27: =C27*'1-Data Input'!$E$3 -> 0 | Q27: =D27*'1-Data Input'!$E$4 -> 0 | R27: =E27*'1-Data Input'!$E$5 -> 0 | S27: =F27*'1-Data Input'!$E$6 -> 0 | T27: =G27*'1-Data Input'!$E$7 -> 0 | U27: =H27*'1-Data Input'!$E$8 -> 0 | V27: =I27*'1-Data Input'!$E$9 -> 0 | W27: =J27*'1-Data Input'!$E$10 -> 0 | X27: =K27*'1-Data Input'!$E$11 -> 0 | Y27: =L27*'1-Data Input'!$E$12 -> 0 | Z27: =M27*'1-Data Input'!$E$13 -> 0
A28: Production profile : | G28: Northern France
A29: Relative Production | N29: Extrapolated Production
A30: H | B30: Jan | C30: Feb | D30: Mar | E30: Apr | F30: May | G30: Jun | H30: Jul | I30: Aug | J30: Sep | K30: Oct | L30: Nov | M30: Dec | N30: H | O30: Jan | P30: Feb | Q30: Mar | R30: Apr | S30: May | T30: Jun | U30: Jul | V30: Aug | W30: Sep | X30: Oct | Y30: Nov | Z30: Dec
A31: 0 | B31: 0 | C31: 0 | D31: 0 | E31: 0 | F31: 0 | G31: 0 | H31: 0 | I31: 0 | J31: 0 | K31: 0 | L31: 0 | M31: 0 | N31: 0 | O31: =B31*'1-Data Input'!$D$2 -> 0 | P31: =C31*'1-Data Input'!$D$3 -> 0 | Q31: =D31*'1-Data Input'!$D$4 -> 0 | R31: =E31*'1-Data Input'!$D$5 -> 0 | S31: =F31*'1-Data Input'!$D$6 -> 0 | T31: =G31*'1-Data Input'!$D$7 -> 0 | U31: =H31*'1-Data Input'!$D$8 -> 0 | V31: =I31*'1-Data Input'!$D$9 -> 0 | W31: =J31*'1-Data Input'!$D$10 -> 0 | X31: =K31*'1-Data Input'!$D$11 -> 0 | Y31: =L31*'1-Data Input'!$D$12 -> 0 | Z31: =M31*'1-Data Input'!$D$13 -> 0
A32: 0.041666667 | B32: 0 | C32: 0 | D32: 0 | E32: 0 | F32: 0 | G32: 0 | H32: 0 | I32: 0 | J32: 0 | K32: 0 | L32: 0 | M32: 0 | N32: 0.041666667 | O32: =B32*'1-Data Input'!$D$2 -> 0 | P32: =C32*'1-Data Input'!$D$3 -> 0 | Q32: =D32*'1-Data Input'!$D$4 -> 0 | R32: =E32*'1-Data Input'!$D$5 -> 0 | S32: =F32*'1-Data Input'!$D$6 -> 0 | T32: =G32*'1-Data Input'!$D$7 -> 0 | U32: =H32*'1-Data Input'!$D$8 -> 0 | V32: =I32*'1-Data Input'!$D$9 -> 0 | W32: =J32*'1-Data Input'!$D$10 -> 0 | X32: =K32*'1-Data Input'!$D$11 -> 0 | Y32: =L32*'1-Data Input'!$D$12 -> 0 | Z32: =M32*'1-Data Input'!$D$13 -> 0
A33: 0.083333333 | B33: 0 | C33: 0 | D33: 0 | E33: 0 | F33: 0 | G33: 0 | H33: 0 | I33: 0 | J33: 0 | K33: 0 | L33: 0 | M33: 0 | N33: 0.083333333 | O33: =B33*'1-Data Input'!$D$2 -> 0 | P33: =C33*'1-Data Input'!$D$3 -> 0 | Q33: =D33*'1-Data Input'!$D$4 -> 0 | R33: =E33*'1-Data Input'!$D$5 -> 0 | S33: =F33*'1-Data Input'!$D$6 -> 0 | T33: =G33*'1-Data Input'!$D$7 -> 0 | U33: =H33*'1-Data Input'!$D$8 -> 0 | V33: =I33*'1-Data Input'!$D$9 -> 0 | W33: =J33*'1-Data Input'!$D$10 -> 0 | X33: =K33*'1-Data Input'!$D$11 -> 0 | Y33: =L33*'1-Data Input'!$D$12 -> 0 | Z33: =M33*'1-Data Input'!$D$13 -> 0
A34: 0.125 | B34: 0 | C34: 0 | D34: 0 | E34: 0 | F34: 0 | G34: 0 | H34: 0 | I34: 0 | J34: 0 | K34: 0 | L34: 0 | M34: 0 | N34: 0.125 | O34: =B34*'1-Data Input'!$D$2 -> 0 | P34: =C34*'1-Data Input'!$D$3 -> 0 | Q34: =D34*'1-Data Input'!$D$4 -> 0 | R34: =E34*'1-Data Input'!$D$5 -> 0 | S34: =F34*'1-Data Input'!$D$6 -> 0 | T34: =G34*'1-Data Input'!$D$7 -> 0 | U34: =H34*'1-Data Input'!$D$8 -> 0 | V34: =I34*'1-Data Input'!$D$9 -> 0 | W34: =J34*'1-Data Input'!$D$10 -> 0 | X34: =K34*'1-Data Input'!$D$11 -> 0 | Y34: =L34*'1-Data Input'!$D$12 -> 0 | Z34: =M34*'1-Data Input'!$D$13 -> 0
A35: 0.16666667 | B35: 0 | C35: 0 | D35: 0 | E35: 0 | F35: 0 | G35: 0 | H35: 0 | I35: 0 | J35: 0 | K35: 0 | L35: 0 | M35: 0 | N35: 0.16666667 | O35: =B35*'1-Data Input'!$D$2 -> 0 | P35: =C35*'1-Data Input'!$D$3 -> 0 | Q35: =D35*'1-Data Input'!$D$4 -> 0 | R35: =E35*'1-Data Input'!$D$5 -> 0 | S35: =F35*'1-Data Input'!$D$6 -> 0 | T35: =G35*'1-Data Input'!$D$7 -> 0 | U35: =H35*'1-Data Input'!$D$8 -> 0 | V35: =I35*'1-Data Input'!$D$9 -> 0 | W35: =J35*'1-Data Input'!$D$10 -> 0 | X35: =K35*'1-Data Input'!$D$11 -> 0 | Y35: =L35*'1-Data Input'!$D$12 -> 0 | Z35: =M35*'1-Data Input'!$D$13 -> 0
A36: 0.20833333 | B36: 0 | C36: 0 | D36: 0 | E36: 0 | F36: 0.0016694641 | G36: 0.0066202879 | H36: 0.0019306895 | I36: 0 | J36: 0 | K36: 0 | L36: 0 | M36: 0 | N36: 0.20833333 | O36: =B36*'1-Data Input'!$D$2 -> 0 | P36: =C36*'1-Data Input'!$D$3 -> 0 | Q36: =D36*'1-Data Input'!$D$4 -> 0 | R36: =E36*'1-Data Input'!$D$5 -> 0 | S36: =F36*'1-Data Input'!$D$6 -> 0 | T36: =G36*'1-Data Input'!$D$7 -> 0 | U36: =H36*'1-Data Input'!$D$8 -> 0 | V36: =I36*'1-Data Input'!$D$9 -> 0 | W36: =J36*'1-Data Input'!$D$10 -> 0 | X36: =K36*'1-Data Input'!$D$11 -> 0 | Y36: =L36*'1-Data Input'!$D$12 -> 0 | Z36: =M36*'1-Data Input'!$D$13 -> 0
A37: 0.25 | B37: 0 | C37: 0 | D37: 0 | E37: 0.0040167692 | F37: 0.016239159 | G37: 0.020198459 | H37: 0.015534043 | I37: 0.008546055 | J37: 6.859195e-05 | K37: 0 | L37: 0 | M37: 0 | N37: 0.25 | O37: =B37*'1-Data Input'!$D$2 -> 0 | P37: =C37*'1-Data Input'!$D$3 -> 0 | Q37: =D37*'1-Data Input'!$D$4 -> 0 | R37: =E37*'1-Data Input'!$D$5 -> 0 | S37: =F37*'1-Data Input'!$D$6 -> 0 | T37: =G37*'1-Data Input'!$D$7 -> 0 | U37: =H37*'1-Data Input'!$D$8 -> 0 | V37: =I37*'1-Data Input'!$D$9 -> 0 | W37: =J37*'1-Data Input'!$D$10 -> 0 | X37: =K37*'1-Data Input'!$D$11 -> 0 | Y37: =L37*'1-Data Input'!$D$12 -> 0 | Z37: =M37*'1-Data Input'!$D$13 -> 0
A38: 0.29166667 | B38: 0 | C38: 0 | D38: 0.0059357523 | E38: 0.02756773 | F38: 0.042436399 | G38: 0.045794582 | H38: 0.040167483 | I38: 0.035338462 | J38: 0.01830796 | K38: 0.0028633054 | L38: 0.00089330427 | M38: 0 | N38: 0.29166667 | O38: =B38*'1-Data Input'!$D$2 -> 0 | P38: =C38*'1-Data Input'!$D$3 -> 0 | Q38: =D38*'1-Data Input'!$D$4 -> 0 | R38: =E38*'1-Data Input'!$D$5 -> 0 | S38: =F38*'1-Data Input'!$D$6 -> 0 | T38: =G38*'1-Data Input'!$D$7 -> 0 | U38: =H38*'1-Data Input'!$D$8 -> 0 | V38: =I38*'1-Data Input'!$D$9 -> 0 | W38: =J38*'1-Data Input'!$D$10 -> 0 | X38: =K38*'1-Data Input'!$D$11 -> 0 | Y38: =L38*'1-Data Input'!$D$12 -> 0 | Z38: =M38*'1-Data Input'!$D$13 -> 0
A39: 0.33333333 | B39: 0 | C39: 0.0054723383 | D39: 0.036925596 | E39: 0.059886227 | F39: 0.071021361 | G39: 0.06970555 | H39: 0.06491654 | I39: 0.064866111 | J39: 0.050210942 | K39: 0.036782153 | L39: 0.018917531 | M39: 0.0063451587 | N39: 0.33333333 | O39: =B39*'1-Data Input'!$D$2 -> 0 | P39: =C39*'1-Data Input'!$D$3 -> 0 | Q39: =D39*'1-Data Input'!$D$4 -> 0 | R39: =E39*'1-Data Input'!$D$5 -> 0 | S39: =F39*'1-Data Input'!$D$6 -> 0 | T39: =G39*'1-Data Input'!$D$7 -> 0 | U39: =H39*'1-Data Input'!$D$8 -> 0 | V39: =I39*'1-Data Input'!$D$9 -> 0 | W39: =J39*'1-Data Input'!$D$10 -> 0 | X39: =K39*'1-Data Input'!$D$11 -> 0 | Y39: =L39*'1-Data Input'!$D$12 -> 0 | Z39: =M39*'1-Data Input'!$D$13 -> 0
A40: 0.375 | B40: 0.022603022 | C40: 0.049162935 | D40: 0.076237312 | E40: 0.090771844 | F40: 0.092683636 | G40: 0.089369119 | H40: 0.089106656 | I40: 0.090597644 | J40: 0.086391761 | K40: 0.087049798 | L40: 0.072839329 | M40: 0.046005884 | N40: 0.375 | O40: =B40*'1-Data Input'!$D$2 -> 0 | P40: =C40*'1-Data Input'!$D$3 -> 0 | Q40: =D40*'1-Data Input'!$D$4 -> 0 | R40: =E40*'1-Data Input'!$D$5 -> 0 | S40: =F40*'1-Data Input'!$D$6 -> 0 | T40: =G40*'1-Data Input'!$D$7 -> 0 | U40: =H40*'1-Data Input'!$D$8 -> 0 | V40: =I40*'1-Data Input'!$D$9 -> 0 | W40: =J40*'1-Data Input'!$D$10 -> 0 | X40: =K40*'1-Data Input'!$D$11 -> 0 | Y40: =L40*'1-Data Input'!$D$12 -> 0 | Z40: =M40*'1-Data Input'!$D$13 -> 0
A41: 0.41666667 | B41: 0.11875715 | C41: 0.093211644 | D41: 0.10586585 | E41: 0.10833984 | F41: 0.11060387 | G41: 0.10355447 | H41: 0.10735759 | I41: 0.10501304 | J41: 0.10802933 | K41: 0.13277957 | L41: 0.13443926 | M41: 0.11370772 | N41: 0.41666667 | O41: =B41*'1-Data Input'!$D$2 -> 0 | P41: =C41*'1-Data Input'!$D$3 -> 0 | Q41: =D41*'1-Data Input'!$D$4 -> 0 | R41: =E41*'1-Data Input'!$D$5 -> 0 | S41: =F41*'1-Data Input'!$D$6 -> 0 | T41: =G41*'1-Data Input'!$D$7 -> 0 | U41: =H41*'1-Data Input'!$D$8 -> 0 | V41: =I41*'1-Data Input'!$D$9 -> 0 | W41: =J41*'1-Data Input'!$D$10 -> 0 | X41: =K41*'1-Data Input'!$D$11 -> 0 | Y41: =L41*'1-Data Input'!$D$12 -> 0 | Z41: =M41*'1-Data Input'!$D$13 -> 0
A42: 0.45833333 | B42: 0.18836314 | C42: 0.12008607 | D42: 0.12025077 | E42: 0.11877613 | F42: 0.11264811 | G42: 0.093992291 | H42: 0.10311793 | I42: 0.11568575 | J42: 0.12799489 | K42: 0.15325271 | L42: 0.16527374 | M42: 0.16481105 | N42: 0.45833333 | O42: =B42*'1-Data Input'!$D$2 -> 0 | P42: =C42*'1-Data Input'!$D$3 -> 0 | Q42: =D42*'1-Data Input'!$D$4 -> 0 | R42: =E42*'1-Data Input'!$D$5 -> 0 | S42: =F42*'1-Data Input'!$D$6 -> 0 | T42: =G42*'1-Data Input'!$D$7 -> 0 | U42: =H42*'1-Data Input'!$D$8 -> 0 | V42: =I42*'1-Data Input'!$D$9 -> 0 | W42: =J42*'1-Data Input'!$D$10 -> 0 | X42: =K42*'1-Data Input'!$D$11 -> 0 | Y42: =L42*'1-Data Input'!$D$12 -> 0 | Z42: =M42*'1-Data Input'!$D$13 -> 0
... A54: 0.95833333 | B54: 0 | C54: 0 | D54: 0 | E54: 0 | F54: 0 | G54: 0 | H54: 0 | I54: 0 | J54: 0 | K54: 0 | L54: 0 | M54: 0 | N54: 0.95833333 | O54: =B54*'1-Data Input'!$D$2 -> 0 | P54: =C54*'1-Data Input'!$D$3 -> 0 | Q54: =D54*'1-Data Input'!$D$4 -> 0 | R54: =E54*'1-Data Input'!$D$5 -> 0 | S54: =F54*'1-Data Input'!$D$6 -> 0 | T54: =G54*'1-Data Input'!$D$7 -> 0 | U54: =H54*'1-Data Input'!$D$8 -> 0 | V54: =I54*'1-Data Input'!$D$9 -> 0 | W54: =J54*'1-Data Input'!$D$10 -> 0 | X54: =K54*'1-Data Input'!$D$11 -> 0 | Y54: =L54*'1-Data Input'!$D$12 -> 0 | Z54: =M54*'1-Data Input'!$D$13 -> 0
A55: Production profile : | G55: Eastern France
A56: Relative Production | N56: Extrapolated Production
A57: H | B57: Jan | C57: Feb | D57: Mar | E57: Apr | F57: May | G57: Jun | H57: Jul | I57: Aug | J57: Sep | K57: Oct | L57: Nov | M57: Dec | N57: H | O57: Jan | P57: Feb | Q57: Mar | R57: Apr | S57: May | T57: Jun | U57: Jul | V57: Aug | W57: Sep | X57: Oct | Y57: Nov | Z57: Dec
...

Sheet 4-Battery needs
A1: Delta between production and consumption (average day)
A2: Time | B2: Jan | C2: Feb | D2: Mar | E2: Apr | F2: May | G2: Jun | H2: Jul | I2: Aug | J2: Sep | K2: Oct | L2: Nov | M2: Dec | O2: DATA
A3: 0 | B3: {=(OFFSET(INDIRECT("'3-Production profile'!"&ADDRESS(MATCH($P$4, '3-Production profile'!$G:$G, 0), 7)), 3, 8, 24, 12))-(OFFSET(INDIRECT("'2-Consumption profiles'!"&ADDRESS(MATCH($P$3, '2-Consumption profiles'!$G:$G, 0), 7)), 3, 8, 24, 12))} -> 0 | C3: 0 | D3: 0 | E3: 0 | F3: 0 | G3: 0 | H3: 0 | I3: 0 | J3: 0 | K3: 0 | L3: 0 | M3: 0 | O3: Consumption profile : | P3: ='1-Data Input'!C15 -> Office building with gas heating, with A/C
A4: 0.041666667 | B4: 0 | C4: 0 | D4: 0 | E4: 0 | F4: 0 | G4: 0 | H4: 0 | I4: 0 | J4: 0 | K4: 0 | L4: 0 | M4: 0 | O4: Production profile : | P4: ='1-Data Input'!C16 -> Belgium
A5: 0.083333333 | B5: 0 | C5: 0 | D5: 0 | E5: 0 | F5: 0 | G5: 0 | H5: 0 | I5: 0 | J5: 0 | K5: 0 | L5: 0 | M5: 0
A6: 0.125 | B6: 0 | C6: 0 | D6: 0 | E6: 0 | F6: 0 | G6: 0 | H6: 0 | I6: 0 | J6: 0 | K6: 0 | L6: 0 | M6: 0 | O6: OUTPUT
A7: 0.16666667 | B7: 0 | C7: 0 | D7: 0 | E7: 0 | F7: 0 | G7: 0 | H7: 0 | I7: 0 | J7: 0 | K7: 0 | L7: 0 | M7: 0 | O7: Avg Excess Needs | P7: =AVERAGE(B80:M80) -> 0
A8: 0.20833333 | B8: 0 | C8: 0 | D8: 0 | E8: 0 | F8: 0 | G8: 0 | H8: 0 | I8: 0 | J8: 0 | K8: 0 | L8: 0 | M8: 0 | O8: Min Excess Needs | P8: =MIN(B80:M80) -> 0
A9: 0.25 | B9: 0 | C9: 0 | D9: 0 | E9: 0 | F9: 0 | G9: 0 | H9: 0 | I9: 0 | J9: 0 | K9: 0 | L9: 0 | M9: 0 | O9: Max Excess Needs | P9: =MAX(B80:M80) -> 0
A10: 0.29166667 | B10: 0 | C10: 0 | D10: 0 | E10: 0 | F10: 0 | G10: 0 | H10: 0 | I10: 0 | J10: 0 | K10: 0 | L10: 0 | M10: 0 | O10: Avg Excess Prod | P10: =AVERAGE(B53:M53) -> 0
A11: 0.33333333 | B11: 0 | C11: 0 | D11: 0 | E11: 0 | F11: 0 | G11: 0 | H11: 0 | I11: 0 | J11: 0 | K11: 0 | L11: 0 | M11: 0 | O11: Min Excess Prod | P11: =MIN(B53:M53) -> 0
A12: 0.375 | B12: 0 | C12: 0 | D12: 0 | E12: 0 | F12: 0 | G12: 0 | H12: 0 | I12: 0 | J12: 0 | K12: 0 | L12: 0 | M12: 0 | O12: Max Excess Prod | P12: =MAX(B53:M53) -> 0
A13: 0.41666667 | B13: 0 | C13: 0 | D13: 0 | E13: 0 | F13: 0 | G13: 0 | H13: 0 | I13: 0 | J13: 0 | K13: 0 | L13: 0 | M13: 0 | O13: Avg battery needs | P13: =MIN(P7, P10) -> 0
A14: 0.45833333 | B14: 0 | C14: 0 | D14: 0 | E14: 0 | F14: 0 | G14: 0 | H14: 0 | I14: 0 | J14: 0 | K14: 0 | L14: 0 | M14: 0 | O14: Min battery needs | P14: =MIN(P8, P11) -> 0
A15: 0.5 | B15: 0 | C15: 0 | D15: 0 | E15: 0 | F15: 0 | G15: 0 | H15: 0 | I15: 0 | J15: 0 | K15: 0 | L15: 0 | M15: 0 | O15: Max battery needs | P15: =MIN(P9, P12) -> 0
A16: 0.54166667 | B16: 0 | C16: 0 | D16: 0 | E16: 0 | F16: 0 | G16: 0 | H16: 0 | I16: 0 | J16: 0 | K16: 0 | L16: 0 | M16: 0
A17: 0.58333333 | B17: 0 | C17: 0 | D17: 0 | E17: 0 | F17: 0 | G17: 0 | H17: 0 | I17: 0 | J17: 0 | K17: 0 | L17: 0 | M17: 0 | O17: Offtake tariff (MWh) | P17: 250
A18: 0.625 | B18: 0 | C18: 0 | D18: 0 | E18: 0 | F18: 0 | G18: 0 | H18: 0 | I18: 0 | J18: 0 | K18: 0 | L18: 0 | M18: 0 | O18: Injection tariff (MWh) | P18: 50
A19: 0.66666667 | B19: 0 | C19: 0 | D19: 0 | E19: 0 | F19: 0 | G19: 0 | H19: 0 | I19: 0 | J19: 0 | K19: 0 | L19: 0 | M19: 0
A20: 0.70833333 | B20: 0 | C20: 0 | D20: 0 | E20: 0 | F20: 0 | G20: 0 | H20: 0 | I20: 0 | J20: 0 | K20: 0 | L20: 0 | M20: 0 | O20: Yearly savings | P20: =365*P13*(P17-P18)/1000 -> 0
A21: 0.75 | B21: 0 | C21: 0 | D21: 0 | E21: 0 | F21: 0 | G21: 0 | H21: 0 | I21: 0 | J21: 0 | K21: 0 | L21: 0 | M21: 0
A22: 0.79166667 | B22: 0 | C22: 0 | D22: 0 | E22: 0 | F22: 0 | G22: 0 | H22: 0 | I22: 0 | J22: 0 | K22: 0 | L22: 0 | M22: 0
A23: 0.83333333 | B23: 0 | C23: 0 | D23: 0 | E23: 0 | F23: 0 | G23: 0 | H23: 0 | I23: 0 | J23: 0 | K23: 0 | L23: 0 | M23: 0
A24: 0.875 | B24: 0 | C24: 0 | D24: 0 | E24: 0 | F24: 0 | G24: 0 | H24: 0 | I24: 0 | J24: 0 | K24: 0 | L24: 0 | M24: 0
A25: 0.91666667 | B25: 0 | C25: 0 | D25: 0 | E25: 0 | F25: 0 | G25: 0 | H25: 0 | I25: 0 | J25: 0 | K25: 0 | L25: 0 | M25: 0
A26: 0.95833333 | B26: 0 | C26: 0 | D26: 0 | E26: 0 | F26: 0 | G26: 0 | H26: 0 | I26: 0 | J26: 0 | K26: 0 | L26: 0 | M26: 0
A27: Injection (average day)
A28: Time | B28: Jan | C28: Feb | D28: Mar | E28: Apr | F28: May | G28: Jun | H28: Jul | I28: Aug | J28: Sep | K28: Oct | L28: Nov | M28: Dec
A29: 0 | B29: =MAX(B3, 0) -> 0 | C29: =MAX(C3, 0) -> 0 | D29: =MAX(D3, 0) -> 0 | E29: =MAX(E3, 0) -> 0 | F29: =MAX(F3, 0) -> 0 | G29: =MAX(G3, 0) -> 0 | H29: =MAX(H3, 0) -> 0 | I29: =MAX(I3, 0) -> 0 | ... M29: =MAX(M3, 0) -> 0
A30: 0.041666667 | B30: =MAX(B4, 0) -> 0 | C30: =MAX(C4, 0) -> 0 | D30: =MAX(D4, 0) -> 0 | E30: =MAX(E4, 0) -> 0 | F30: =MAX(F4, 0) -> 0 | G30: =MAX(G4, 0) -> 0 | H30: =MAX(H4, 0) -> 0 | I30: =MAX(I4, 0) -> 0 | ... M30: =MAX(M4, 0) -> 0
A31: 0.083333333 | B31: =MAX(B5, 0) -> 0 | C31: =MAX(C5, 0) -> 0 | D31: =MAX(D5, 0) -> 0 | E31: =MAX(E5, 0) -> 0 | F31: =MAX(F5, 0) -> 0 | G31: =MAX(G5, 0) -> 0 | H31: =MAX(H5, 0) -> 0 | I31: =MAX(I5, 0) -> 0 | ... M31: =MAX(M5, 0) -> 0
A32: 0.125 | B32: =MAX(B6, 0) -> 0 | C32: =MAX(C6, 0) -> 0 | D32: =MAX(D6, 0) -> 0 | E32: =MAX(E6, 0) -> 0 | F32: =MAX(F6, 0) -> 0 | G32: =MAX(G6, 0) -> 0 | H32: =MAX(H6, 0) -> 0 | I32: =MAX(I6, 0) -> 0 | ... M32: =MAX(M6, 0) -> 0
A33: 0.16666667 | B33: =MAX(B7, 0) -> 0 | C33: =MAX(C7, 0) -> 0 | D33: =MAX(D7, 0) -> 0 | E33: =MAX(E7, 0) -> 0 | F33: =MAX(F7, 0) -> 0 | G33: =MAX(G7, 0) -> 0 | H33: =MAX(H7, 0) -> 0 | I33: =MAX(I7, 0) -> 0 | ... M33: =MAX(M7, 0) -> 0
A34: 0.20833333 | B34: =MAX(B8, 0) -> 0 | C34: =MAX(C8, 0) -> 0 | D34: =MAX(D8, 0) -> 0 | E34: =MAX(E8, 0) -> 0 | F34: =MAX(F8, 0) -> 0 | G34: =MAX(G8, 0) -> 0 | H34: =MAX(H8, 0) -> 0 | I34: =MAX(I8, 0) -> 0 | ... M34: =MAX(M8, 0) -> 0
A35: 0.25 | B35: =MAX(B9, 0) -> 0 | C35: =MAX(C9, 0) -> 0 | D35: =MAX(D9, 0) -> 0 | E35: =MAX(E9, 0) -> 0 | F35: =MAX(F9, 0) -> 0 | G35: =MAX(G9, 0) -> 0 | H35: =MAX(H9, 0) -> 0 | I35: =MAX(I9, 0) -> 0 | ... M35: =MAX(M9, 0) -> 0
A36: 0.29166667 | B36: =MAX(B10, 0) -> 0 | C36: =MAX(C10, 0) -> 0 | D36: =MAX(D10, 0) -> 0 | E36: =MAX(E10, 0) -> 0 | F36: =MAX(F10, 0) -> 0 | G36: =MAX(G10, 0) -> 0 | H36: =MAX(H10, 0) -> 0 | I36: =MAX(I10, 0) -> 0 | ... M36: =MAX(M10, 0) -> 0
A37: 0.33333333 | B37: =MAX(B11, 0) -> 0 | C37: =MAX(C11, 0) -> 0 | D37: =MAX(D11, 0) -> 0 | E37: =MAX(E11, 0) -> 0 | F37: =MAX(F11, 0) -> 0 | G37: =MAX(G11, 0) -> 0 | H37: =MAX(H11, 0) -> 0 | I37: =MAX(I11, 0) -> 0 | ... M37: =MAX(M11, 0) -> 0
A38: 0.375 | B38: =MAX(B12, 0) -> 0 | C38: =MAX(C12, 0) -> 0 | D38: =MAX(D12, 0) -> 0 | E38: =MAX(E12, 0) -> 0 | F38: =MAX(F12, 0) -> 0 | G38: =MAX(G12, 0) -> 0 | H38: =MAX(H12, 0) -> 0 | I38: =MAX(I12, 0) -> 0 | ... M38: =MAX(M12, 0) -> 0
A39: 0.41666667 | B39: =MAX(B13, 0) -> 0 | C39: =MAX(C13, 0) -> 0 | D39: =MAX(D13, 0) -> 0 | E39: =MAX(E13, 0) -> 0 | F39: =MAX(F13, 0) -> 0 | G39: =MAX(G13, 0) -> 0 | H39: =MAX(H13, 0) -> 0 | I39: =MAX(I13, 0) -> 0 | ... M39: =MAX(M13, 0) -> 0
A40: 0.45833333 | B40: =MAX(B14, 0) -> 0 | C40: =MAX(C14, 0) -> 0 | D40: =MAX(D14, 0) -> 0 | E40: =MAX(E14, 0) -> 0 | F40: =MAX(F14, 0) -> 0 | G40: =MAX(G14, 0) -> 0 | H40: =MAX(H14, 0) -> 0 | I40: =MAX(I14, 0) -> 0 | ... M40: =MAX(M14, 0) -> 0
...

Sheet README
A1: EXPLANATION | J1: HOW TO USE THE TOOL
K25: DISCLAIMER: This document is the intellectual property of Watt4Ever srl. Watt4Ever srl authorizes its use strictly for educational reasons. It may not be reproduced, copied, or broadcasted under any circumstances without the written authorization of Watt4Ever srl.
